Workbook

Sheet SUM
GR1: =GR4/$Q$4/10^9 -> 0.027998133 | GS1: =GS4/$Q$4/10^9 -> 0.026918937 | GT1: =GT4/$Q$4/10^9 -> 0.026556074 | GU1: =GU4/$Q$4/10^9 -> 0.029203748 | GV1: =GV4/$Q$4/10^9 -> 0.034047185 | GW1: =GW4/$Q$4/10^9 -> 0.009467153 | GX1: =GX4/$Q$4/10^9 -> 0.033561287 | GY1: =GY4/$Q$4/10^9 -> 0.032310376 | ... NS1: =NS4/$Q$4/10^9 -> 0.034883452 | OP1: =OP4/$Q$4/10^9 -> 0.0073278071 | OQ1: =OQ4/$Q$4/10^9 -> 0.029260401 | OR1: =OR4/$Q$4/10^9 -> 0.024396248 | OS1: =OS4/$Q$4/10^9 -> 0.0089733606 | OT1: =OT4/$Q$4/10^9 -> 0.03476808 | OU1: =OU4/$Q$4/10^9 -> 0.031978946 | OV1: =OV4/$Q$4/10^9 -> 0.032801344 | OW1: =OW4/$Q$4/10^9 -> 0.026899608 | ... PT1: =PT4/$Q$4/10^9 -> 0
B2: Channel | C2: Sub Channel | D2: MTD - Jan | L2: MTD | O2: KPI - Nov | S2: 45658 | T2: 45659 | U2: 45660 | V2: 45661 | W2: 45662 | X2: 45663 | Y2: 45664 | Z2: 45665 | AA2: 45666 | AB2: 45667 | AC2: 45668 | AD2: 45669 | AE2: 45670 | AF2: 45671 | AG2: 45672 | AH2: 45673 | AI2: 45674 | AJ2: 45675 | AK2: 45676 | AL2: 45677 | AM2: 45678 | AN2: 45679 | AO2: 45680 | AP2: 45681 | AQ2: 45682 | AR2: 45683 | AS2: 45684 | AT2: 45685 | AU2: 45686 | AV2: 45687 | AW2: 45688 | AX2: 45689 | AY2: 45690 | AZ2: 45691 | BA2: 45692 | BB2: 45693 | BC2: 45694 | BD2: 45695 | BE2: 45696 | BF2: 45697 | BG2: 45698 | BH2: 45699 | BI2: 45700 | BJ2: 45701 | BK2: 45702 | BL2: 45703 | BM2: 45704 | BN2: 45705 | BO2: 45706 | BP2: 45707 | BQ2: 45708 | BR2: 45709 | BS2: 45710 | BT2: 45711 | BU2: 45712 | BV2: 45713 | BW2: 45714 | BX2: 45715 | BY2: 45716 | BZ2: 45717 | CA2: 45718 | CB2: 45719 | CC2: 45720 | CD2: 45721 | CE2: 45722 | CF2: 45723 | CG2: 45724 | CH2: 45725 | CI2: 45726 | CJ2: 45727 | CK2: 45728 | CL2: 45729 | CM2: 45730 | CN2: 45731 | CO2: 45732 | CP2: 45733 | CQ2: 45734 | CR2: 45735 | CS2: 45736 | CT2: 45737 | CU2: 45738 | CV2: 45739 | CW2: 45740 | CX2: 45741 | CY2: 45742 | CZ2: 45743 | DA2: 45744 | DB2: 45745 | DC2: 45746 | DD2: 45747 | DE2: 45748 | DF2: 45749 | DG2: 45750 | DH2: 45751 | DI2: 45752 | DJ2: 45753 | DK2: 45754 | DL2: 45755 | DM2: 45756 | DN2: 45757 | DO2: 45758 | DP2: 45759 | DQ2: 45760 | DR2: 45761 | DS2: 45762 | DT2: 45763 | DU2: 45764 | DV2: 45765 | DW2: 45766 | DX2: 45767 | DY2: 45768 | DZ2: 45769 | EA2: 45770 | EB2: 45771 | EC2: 45772 | ED2: 45773 | EE2: 45774 | EF2: 45775 | EG2: 45776 | EH2: 45777 | EI2: 45778 | EJ2: 45779 | EK2: 45780 | EL2: 45781 | EM2: 45782 | EN2: 45783 | EO2: 45784 | EP2: 45785 | EQ2: 45786 | ER2: 45787 | ES2: 45788 | ET2: 45789 | EU2: 45790 | EV2: 45791 | EW2: 45792 | EX2: 45793 | EY2: 45794 | EZ2: 45795 | FA2: 45796 | FB2: 45797 | FC2: 45798 | FD2: 45799 | FE2: 45800 | FF2: 45801 | FG2: 45802 | FH2: 45803 | FI2: 45804 | FJ2: 45805 | FK2: 45806 | FL2: 45807 | FM2: 45808 | FN2: 45809 | FO2: 45810 | FP2: 45811 | FQ2: 45812 | FR2: 45813 | FS2: 45814 | FT2: 45815 | FU2: 45816 | FV2: 45817 | FW2: 45818 | FX2: 45819 | FY2: 45820 | FZ2: 45821 | GA2: 45822 | GB2: 45823 | GC2: 45824 | GD2: 45825 | GE2: 45826 | GF2: 45827 | GG2: 45828 | GH2: 45829 | GI2: 45830 | GJ2: 45831 | GK2: 45832 | GL2: 45833 | GM2: 45834 | GN2: 45835 | GO2: 45836 | GP2: 45837 | GQ2: 45838 | GR2: 45839 | GS2: 45840 | GT2: 45841 | GU2: 45842 | GV2: 45843 | GW2: 45844 | GX2: 45845 | GY2: 45846 | GZ2: 45847 | HA2: 45848 | HB2: 45849 | HC2: 45850 | HD2: 45851 | HE2: 45852 | HF2: 45853 | HG2: 45854 | HH2: 45855 | HI2: 45856 | HJ2: 45857 | HK2: 45858 | HL2: 45859 | HM2: 45860 | HN2: 45861 | HO2: 45862 | HP2: 45863 | HQ2: 45864 | HR2: 45865 | HS2: 45866 | HT2: 45867 | HU2: 45868 | HV2: 45869 | HW2: 45870 | HX2: 45871 | HY2: 45872 | HZ2: 45873 | IA2: 45874 | IB2: 45875 | IC2: 45876 | ID2: 45877 | IE2: 45878 | IF2: 45879 | IG2: 45880 | IH2: 45881 | II2: 45882 | IJ2: 45883 | IK2: 45884 | IL2: 45885 | IM2: 45886 | IN2: 45887 | IO2: 45888 | IP2: 45889 | IQ2: 45890 | IR2: 45891 | IS2: 45892 | IT2: 45893 | IU2: 45894 | IV2: 45895 | IW2: 45896 | IX2: 45897 | IY2: 45898 | IZ2: 45899 | JA2: 45900 | JB2: 45901 | JC2: 45902 | JD2: 45903 | JE2: 45904 | JF2: 45905 | JG2: 45906 | JH2: 45907 | JI2: 45908 | JJ2: 45909 | JK2: 45910 | JL2: 45911 | JM2: 45912 | JN2: 45913 | JO2: 45914 | JP2: 45915 | JQ2: 45916 | JR2: 45917 | JS2: 45918 | JT2: 45919 | JU2: 45920 | JV2: 45921 | JW2: 45922 | JX2: 45923 | JY2: 45924 | JZ2: 45925 | KA2: 45926 | KB2: 45927 | KC2: 45928 | KD2: 45929 | KE2: 45930 | KF2: 45931 | KG2: 45932 | KH2: 45933 | KI2: 45934 | KJ2: 45935 | KK2: 45936 | KL2: 45937 | KM2: 45938 | KN2: 45939 | KO2: 45940 | KP2: 45941 | KQ2: 45942 | KR2: 45943 | KS2: 45944 | KT2: 45945 | KU2: 45946 | KV2: 45947 | KW2: 45948 | KX2: 45949 | KY2: 45950 | KZ2: 45951 | LA2: 45952 | LB2: 45953 | LC2: 45954 | LD2: 45955 | LE2: 45956 | LF2: 45957 | LG2: 45958 | LH2: 45959 | LI2: 45960 | LJ2: 45961 | LK2: 45962 | LL2: 45963 | LM2: 45964 | LN2: 45965 | LO2: 45966 | LP2: 45967 | LQ2: 45968 | LR2: 45969 | LS2: 45970 | LT2: 45971 | LU2: 45972 | LV2: 45973 | LW2: 45974 | LX2: 45975 | LY2: 45976 | LZ2: 45977 | MA2: 45978 | MB2: 45979 | MC2: 45980 | MD2: 45981 | ME2: 45982 | MF2: 45983 | MG2: 45984 | MH2: 45985 | MI2: 45986 | MJ2: 45987 | MK2: 45988 | ML2: 45989 | MM2: 45990 | MN2: 45991 | MO2: 45992 | MP2: 45993 | MQ2: 45994 | MR2: 45995 | MS2: 45996 | MT2: 45997 | MU2: 45998 | MV2: 45999 | MW2: 46000 | MX2: 46001 | MY2: 46002 | MZ2: 46003 | NA2: 46004 | NB2: 46005 | NC2: 46006 | ND2: 46007 | NE2: 46008 | NF2: 46009 | NG2: 46010 | NH2: 46011 | NI2: 46012 | NJ2: 46013 | NK2: 46014 | NL2: 46015 | NM2: 46016 | NN2: 46017 | NO2: 46018 | NP2: 46019 | NQ2: 46020 | NR2: 46021 | NS2: 46022 | OP2: 46023 | OQ2: 46024 | OR2: 46025 | OS2: 46026 | OT2: 46027 | OU2: 46028 | OV2: 46029 | OW2: 46030 | OX2: 46031 | OY2: 46032 | OZ2: 46033 | PA2: 46034 | PB2: 46035 | PC2: 46036 | PD2: 46037 | PE2: 46038 | PF2: 46039 | PG2: 46040 | PH2: 46041 | PI2: 46042 | PJ2: 46043 | PK2: 46044 | PL2: 46045 | PM2: 46046 | PN2: 46047 | PO2: 46048 | PP2: 46049 | PQ2: 46050 | PR2: 46051 | PS2: 46052 | PT2: 46053
D3: HMTD | E3: HMGPXL | F3: HMSG | G3: HPH | H3: HPEC | I3: HMGKD | J3: R1 | L3: % Contribution | M3: Total Sales | N3: Total Viện | O3: Total | Q3: Total KPI | R3: % KPI | S3: d_revenue | T3: d_revenue | U3: d_revenue | V3: d_revenue | W3: d_revenue | X3: d_revenue | Y3: d_revenue | Z3: d_revenue | AA3: d_revenue | AB3: d_revenue | AC3: d_revenue | AD3: d_revenue | AE3: d_revenue | AF3: d_revenue | AG3: d_revenue | AH3: d_revenue | AI3: d_revenue | AJ3: d_revenue | AK3: d_revenue | AL3: d_revenue | AM3: d_revenue | AN3: d_revenue | AO3: d_revenue | AP3: d_revenue | AQ3: d_revenue | AR3: d_revenue | AS3: d_revenue | AT3: d_revenue | AU3: d_revenue | AV3: d_revenue | AW3: d_revenue | AX3: d_revenue | AY3: d_revenue | AZ3: d_revenue | BA3: d_revenue | BB3: d_revenue | BC3: d_revenue | BD3: d_revenue | BE3: d_revenue | BF3: d_revenue | BG3: d_revenue | BH3: d_revenue | BI3: d_revenue | BJ3: d_revenue | BK3: d_revenue | BL3: d_revenue | BM3: d_revenue | BN3: d_revenue | BO3: d_revenue | BP3: d_revenue | BQ3: d_revenue | BR3: d_revenue | BS3: d_revenue | BT3: d_revenue | BU3: d_revenue | BV3: d_revenue | BW3: d_revenue | BX3: d_revenue | BY3: d_revenue | BZ3: d_revenue | CA3: d_revenue | CB3: d_revenue | CC3: d_revenue | CD3: d_revenue | CE3: d_revenue | CF3: d_revenue | CG3: d_revenue | CH3: d_revenue | CI3: d_revenue | CJ3: d_revenue | CK3: d_revenue | CL3: d_revenue | CM3: d_revenue | CN3: d_revenue | CO3: d_revenue | CP3: d_revenue | CQ3: d_revenue | CR3: d_revenue | CS3: d_revenue | CT3: d_revenue | CU3: d_revenue | CV3: d_revenue | CW3: d_revenue | CX3: d_revenue | CY3: d_revenue | CZ3: d_revenue | DA3: d_revenue | DB3: d_revenue | DC3: d_revenue | DD3: d_revenue | DE3: d_revenue | DF3: d_revenue | DG3: d_revenue | DH3: d_revenue | DI3: d_revenue | DJ3: d_revenue | DK3: d_revenue | DL3: d_revenue | DM3: d_revenue | DN3: d_revenue | DO3: d_revenue | DP3: d_revenue | DQ3: d_revenue | DR3: d_revenue | DS3: d_revenue | DT3: d_revenue | DU3: d_revenue | DV3: d_revenue | DW3: d_revenue | DX3: d_revenue | DY3: d_revenue | DZ3: d_revenue | EA3: d_revenue | EB3: d_revenue | EC3: d_revenue | ED3: d_revenue | EE3: d_revenue | EF3: d_revenue | EG3: d_revenue | EH3: d_revenue | EI3: d_revenue | EJ3: d_revenue | EK3: d_revenue | EL3: d_revenue | EM3: d_revenue | EN3: d_revenue | EO3: d_revenue | EP3: d_revenue | EQ3: d_revenue | ER3: d_revenue | ES3: d_revenue | ET3: d_revenue | EU3: d_revenue | EV3: d_revenue | EW3: d_revenue | EX3: d_revenue | EY3: d_revenue | EZ3: d_revenue | FA3: d_revenue | FB3: d_revenue | FC3: d_revenue | FD3: d_revenue | FE3: d_revenue | FF3: d_revenue | FG3: d_revenue | FH3: d_revenue | FI3: d_revenue | FJ3: d_revenue | FK3: d_revenue | FL3: d_revenue | FM3: d_revenue | FN3: d_revenue | FO3: d_revenue | FP3: d_revenue | FQ3: d_revenue | FR3: d_revenue | FS3: d_revenue | FT3: d_revenue | FU3: d_revenue | FV3: d_revenue | FW3: d_revenue | FX3: d_revenue | FY3: d_revenue | FZ3: d_revenue | GA3: d_revenue | GB3: d_revenue | GC3: d_revenue | GD3: d_revenue | GE3: d_revenue | GF3: d_revenue | GG3: d_revenue | GH3: d_revenue | GI3: d_revenue | GJ3: d_revenue | GK3: d_revenue | GL3: d_revenue | GM3: d_revenue | GN3: d_revenue | GO3: d_revenue | GP3: d_revenue | GQ3: d_revenue | GR3: d_revenue | GS3: d_revenue | GT3: d_revenue | GU3: d_revenue | GV3: d_revenue | GW3: d_revenue | GX3: d_revenue | GY3: d_revenue | GZ3: d_revenue | HA3: d_revenue | HB3: d_revenue | HC3: d_revenue | HD3: d_revenue | HE3: d_revenue | HF3: d_revenue | HG3: d_revenue | HH3: d_revenue | HI3: d_revenue | HJ3: d_revenue | HK3: d_revenue | HL3: d_revenue | HM3: d_revenue | HN3: d_revenue | HO3: d_revenue | HP3: d_revenue | HQ3: d_revenue | HR3: d_revenue | HS3: d_revenue | HT3: d_revenue | HU3: d_revenue | HV3: d_revenue | HW3: d_revenue | HX3: d_revenue | HY3: d_revenue | HZ3: d_revenue | IA3: d_revenue | IB3: d_revenue | IC3: d_revenue | ID3: d_revenue | IE3: d_revenue | IF3: d_revenue | IG3: d_revenue | IH3: d_revenue | II3: d_revenue | IJ3: d_revenue | IK3: d_revenue | IL3: d_revenue | IM3: d_revenue | IN3: d_revenue | IO3: d_revenue | IP3: d_revenue | IQ3: d_revenue | IR3: d_revenue | IS3: d_revenue | IT3: d_revenue | IU3: d_revenue | IV3: d_revenue | IW3: d_revenue | IX3: d_revenue | IY3: d_revenue | IZ3: d_revenue | JA3: d_revenue | JB3: d_revenue | JC3: d_revenue | JD3: d_revenue | JE3: d_revenue | JF3: d_revenue | JG3: d_revenue | JH3: d_revenue | JI3: d_revenue | JJ3: d_revenue | JK3: d_revenue | JL3: d_revenue | JM3: d_revenue | JN3: d_revenue | JO3: d_revenue | JP3: d_revenue | JQ3: d_revenue | JR3: d_revenue | JS3: d_revenue | JT3: d_revenue | JU3: d_revenue | JV3: d_revenue | JW3: d_revenue | JX3: d_revenue | JY3: d_revenue | JZ3: d_revenue | KA3: d_revenue | KB3: d_revenue | KC3: d_revenue | KD3: d_revenue | KE3: d_revenue | KF3: d_revenue | KG3: d_revenue | KH3: d_revenue | KI3: d_revenue | KJ3: d_revenue | KK3: d_revenue | KL3: d_revenue | KM3: d_revenue | KN3: d_revenue | KO3: d_revenue | KP3: d_revenue | KQ3: d_revenue | KR3: d_revenue | KS3: d_revenue | KT3: d_revenue | KU3: d_revenue | KV3: d_revenue | KW3: d_revenue | KX3: d_revenue | KY3: d_revenue | KZ3: d_revenue | LA3: d_revenue | LB3: d_revenue | LC3: d_revenue | LD3: d_revenue | LE3: d_revenue | LF3: d_revenue | LG3: d_revenue | LH3: d_revenue | LI3: d_revenue | LJ3: d_revenue | LK3: d_revenue | LL3: d_revenue | LM3: d_revenue | LN3: d_revenue | LO3: d_revenue | LP3: d_revenue | LQ3: d_revenue | LR3: d_revenue | LS3: d_revenue | LT3: d_revenue | LU3: d_revenue | LV3: d_revenue | LW3: d_revenue | LX3: d_revenue | LY3: d_revenue | LZ3: d_revenue | MA3: d_revenue | MB3: d_revenue | MC3: d_revenue | MD3: d_revenue | ME3: d_revenue | MF3: d_revenue | MG3: d_revenue | MH3: d_revenue | MI3: d_revenue | MJ3: d_revenue | MK3: d_revenue | ML3: d_revenue | MM3: d_revenue | MN3: d_revenue | MO3: d_revenue | MP3: d_revenue | MQ3: d_revenue | MR3: d_revenue | MS3: d_revenue | MT3: d_revenue | MU3: d_revenue | MV3: d_revenue | MW3: d_revenue | MX3: d_revenue | MY3: d_revenue | MZ3: d_revenue | NA3: d_revenue | NB3: d_revenue | NC3: d_revenue | ND3: d_revenue | NE3: d_revenue | NF3: d_revenue | NG3: d_revenue | NH3: d_revenue | NI3: d_revenue | NJ3: d_revenue | NK3: d_revenue | NL3: d_revenue | NM3: d_revenue | NN3: d_revenue | NO3: d_revenue | NP3: d_revenue | NQ3: d_revenue | NR3: d_revenue | NS3: d_revenue | NW3: Rev. Hospital | NX3: Jan | NY3: Feb | NZ3: Mar | OA3: Apr | OB3: May | OC3: Jun | OD3: Jul | OE3: Aug | OF3: Sep | OG3: Oct | OH3: Nov | OI3: Dec | OJ3: Total 2025 | OK3: Q1 | OL3: Q2 | OM3: Q3 | ON3: Q4 | OP3: d_revenue | OQ3: d_revenue | OR3: d_revenue | OS3: d_revenue | OT3: d_revenue | OU3: d_revenue | OV3: d_revenue | OW3: d_revenue | OX3: d_revenue | OY3: d_revenue | OZ3: d_revenue | PA3: d_revenue | PB3: d_revenue | PC3: d_revenue
B4: Total Channel | D4: =SUM(D5:D9) -> 2270 | E4: =SUM(E5:E9) -> 904.19 | F4: =SUM(F5:F9) -> 4519 | G4: =SUM(G5:G9) -> 5995 | H4: =SUM(H5:H9) -> 343 | I4: =SUM(I6:I9) -> 0 | J4: =SUM(J5:J9) -> 14031.19 | L4: =M4/N4 -> 0.11303097 | M4: =J4/10^3 -> 14.03119 | N4: =SUM(OP4:PT4)/10^9 -> 124.13581 | O4: =(Q4*1000-N4)/(31-DAY(TODAY())) -> 22997.849 | P4: R1 | Q4: =SUM(Q5:Q10) -> 253.10047 | R4: =N4/Q4 -> 0.49046059 | S4: 1864710495 | T4: 7236707707 | U4: 6445813442 | V4: 6498128737 | W4: 2521250314 | X4: 6727348061 | Y4: 5727155509 | Z4: 6446776805 | AA4: 5898176688 | AB4: 5887988932 | AC4: 8019668297 | AD4: 1958677580 | AE4: 6367291146 | AF4: 6192702917 | AG4: 7061324576 | AH4: 5918199300 | AI4: 5649910846 | AJ4: 6224258101 | AK4: 2459848641 | AL4: 8325027109 | AM4: 6414402893 | AN4: 5129166417 | AO4: 5679810235 | AP4: 6479361988 | AQ4: 5798326723 | AR4: 2491367543 | AS4: 2696698865 | AT4: 2129629745 | AU4: 597843539 | AV4: 1320933540 | AW4: 1989170050 | AX4: 1207640088 | AY4: 624995423 | AZ4: 6033791892 | BA4: 5718493006 | BB4: 5993381368 | BC4: 5946449347 | BD4: 6810125465 | BE4: 7056575760 | BF4: 2279734804 | BG4: 7233849841 | BH4: 6834543839 | BI4: 6121826827 | BJ4: 6874329796 | BK4: 7032501329 | BL4: 8559687570 | BM4: 1976305782 | BN4: 8691212690 | BO4: 7706477914 | BP4: 8110984635 | BQ4: 7251325785 | BR4: 7362890105 | BS4: 7639502228 | BT4: 2190395781 | BU4: 8899780178 | BV4: 8126471943 | BW4: 7529142469 | BX4: 6088717213 | BY4: 7695851801 | BZ4: 7414850951 | CA4: 2051278431 | CB4: 8278171057 | CC4: 7144629858 | CD4: 7093809927 | CE4: 6909403960 | CF4: 7987877119 | CG4: 8078011701 | CH4: 1706886311 | CI4: 8579035422 | CJ4: 7770020728 | CK4: 7729051695 | CL4: 6437815940 | CM4: 7415436003 | CN4: 7690022665 | CO4: 2086301033 | CP4: 8541920949 | CQ4: 8356397615 | CR4: 8865322725 | CS4: 7475593961 | CT4: 8070891775 | CU4: 7886083468 | CV4: 2769187597 | CW4: 8411391009 | CX4: 6528857777 | CY4: 7405203353 | CZ4: 7103291046 | DA4: 7284186779 | DB4: 8899921083 | DC4: 2270586923 | DD4: 9378364783 | DE4: 6707451210 | DF4: 6838842278 | DG4: 7498302944 | DH4: 7441861868 | DI4: 8583953237 | DJ4: 2193789921 | DK4: 1302294707 | DL4: 9469578664 | DM4: 8083647841 | DN4: 7698908342 | DO4: 6891118034 | DP4: 7888878205 | DQ4: 1904263137 | DR4: 7688875230 | DS4: 7472930158 | DT4: 6972784834 | DU4: 7670063503 | DV4: 7453610873 | DW4: 7983947766 | DX4: 2154090250 | DY4: 7797066246 | DZ4: 6017279527 | EA4: 7459970956 | EB4: 6353508836 | EC4: 6760219144 | ED4: 6516497256 | EE4: 1924162631 | EF4: 7805959709 | EG4: 9050482638 | EH4: 2801257691 | EI4: 950315397 | EJ4: 6770709291 | EK4: 5680826258 | EL4: 2259062303 | EM4: 8159205849 | EN4: 7781122218 | EO4: 7302909726 | EP4: 6916272179 | EQ4: 7826249442 | ER4: 8224724005 | ES4: 2046319069 | ET4: 8604797040 | EU4: 7401023372 | EV4: 6748515323 | EW4: 8036801100 | EX4: 7415397578 | EY4: 7928017796 | EZ4: 1654256386 | FA4: 8554522174 | FB4: 7379292790 | FC4: 7119113386 | FD4: 7453438702 | FE4: 7491569966 | FF4: 7444186725 | FG4: 2048561330 | FH4: 8761007596 | FI4: 8097711576 | FJ4: 6216222838 | FK4: 6786630725 | FL4: 6911906084 | FM4: 8679327743 | FN4: 2512236669 | FO4: 7267594228 | FP4: 7143340239 | FQ4: 7052288229 | FR4: 7466074379 | FS4: 7132998418 | FT4: 8193406699 | FU4: 2211313293 | FV4: 7441489378 | FW4: 7304826437 | FX4: 8113652499 | FY4: 7911493661 | FZ4: 7512421127 | GA4: 7730652232 | GB4: 2389006682 | GC4: 8190521115 | GD4: 7344267231 | GE4: 7290397019 | GF4: 7389201733 | GG4: 7431765864 | GH4: 8160741716 | GI4: 2259159315 | GJ4: 8925104986 | GK4: 8039052458 | GL4: 7595984317 | GM4: 7124020481 | GN4: 6018909044 | GO4: 8199678237 | GP4: 2294223629 | GQ4: 8093293948 | GR4: 7086340558 | GS4: 6813195649 | GT4: 6721354853 | GU4: 7391482265 | GV4: 8617358659 | GW4: 2396140879 | GX4: 8494377620 | GY4: 8177771407 | GZ4: 7736343794 | HA4: 8029242935 | HB4: 8564438912 | HC4: 8407803494 | HD4: 2348606763 | HE4: 8202509386 | HF4: 7950135922 | HG4: 7255138143 | HH4: 7600981777 | HI4: 6870080587 | HJ4: 8130908256 | HK4: 2651992624 | HL4: 8671845356 | HM4: 7364286385 | HN4: 7428474506 | HO4: 7400173854 | HP4: 7544481890 | HQ4: 7091772505 | HR4: 2514084341 | HS4: 9053053616 | HT4: 8140067994 | HU4: 8585802582 | HV4: 8639966843 | HW4: 7999795314 | HX4: 9139846478 | HY4: 2067598080 | HZ4: 7689207195 | IA4: 6872646844 | IB4: 7020207452 | IC4: 6610921589 | ID4: 7414266214 | IE4: 8007199557 | IF4: 2309318714 | IG4: 8657623399 | IH4: 7112932042 | II4: 7189232234 | IJ4: 7127647502 | IK4: 7850667393 | IL4: 8084368458 | IM4: 2392488308 | IN4: 8052925982 | IO4: 7508413758 | IP4: 7505884706 | IQ4: 6274312878 | IR4: 6735899686 | IS4: 7287995168 | IT4: 2111823140 | IU4: 8028218675 | IV4: 6217422390 | IW4: 7796247446 | IX4: 7079590530 | IY4: 9668215411 | IZ4: 9893697162 | JA4: 2652860740 | JB4: 2887941774 | JC4: 1943437069 | JD4: 7199800378 | JE4: 8101265055 | JF4: 7666314258 | JG4: 7860619531 | JH4: 2273940056 | JI4: 8552195784 | JJ4: 7052184662 | JK4: 7117477249 | JL4: 7324833591 | JM4: 9158791399 | JN4: 8590501914 | JO4: 2096245075 | JP4: 8103943757 | JQ4: 7637254483 | JR4: 9450364239 | JS4: 7155638207 | JT4: 6739489618 | JU4: 9525003284 | JV4: 2271523955 | JW4: 9504743935 | JX4: 7114818602 | JY4: 8169254273 | JZ4: 7490649142 | KA4: 8053591503 | KB4: 8875196954 | KC4: 2243656769 | KD4: 9612647717 | KE4: 10762147176 | KF4: 8225529426 | KG4: 8660586857 | KH4: 7176134278 | KI4: 8977024667 | KJ4: 3036150063 | KK4: 10214033024 | KL4: 7353954035 | KM4: 9553748124 | KN4: 8076318223 | KO4: 7847982960 | KP4: 9979971700 | KQ4: 3005060271 | KR4: 9834665702 | KS4: 7643945929 | KT4: 7659500924 | KU4: 8119761290 | KV4: 8055020037 | KW4: 8802944157 | KX4: 2825861048 | KY4: 9261037153 | KZ4: 7258218316 | LA4: 7582034277 | LB4: 8151463301 | LC4: 8177056300 | LD4: 9120984495 | LE4: 3122597035 | LF4: 8150604500 | LG4: 7312121065 | LH4: 7908200044 | LI4: 8641626200 | LJ4: 9006479064 | LK4: 8956074252 | LL4: 2694733068 | LM4: 8470465429 | LN4: 7674655750 | LO4: 7461332773 | LP4: 6865780577 | LQ4: 7620299468 | LR4: 9071552738 | LS4: 2394978972 | LT4: 7909106189 | LU4: 8993443644 | LV4: 6636456806 | LW4: 7032783653 | LX4: 6808301804 | LY4: 8521573961 | LZ4: 2293732741 | MA4: 8862421674 | MB4: 10181493334 | MC4: 7461330979 | MD4: 6541264474 | ME4: 8782542389 | MF4: 8100586743 | MG4: 2349751244 | MH4: 11274418191 | MI4: 8357508907 | MJ4: 8864623972 | MK4: 7715838695 | ML4: 8729681144 | MM4: 10383244884 | MN4: 2773341995 | MO4: 8459780902 | MP4: 8057545219 | MQ4: 7904255784 | MR4: 8034011413 | MS4: 8569524091 | MT4: 8361492131 | MU4: 2168328129 | MV4: 8109468868 | MW4: 7847277923 | MX4: 8289294161 | MY4: 8155615395 | MZ4: 7454871334 | NA4: 7580177494 | NB4: 2422688450 | NC4: 8166927871 | ND4: 7914715944 | NE4: 8498681533 | NF4: 7339000052 | NG4: 8369898873 | NH4: 10200225431 | NI4: 2621384663 | NJ4: 9390307666 | NK4: 8120969514 | NL4: 7812689798 | NM4: 8654289898 | NN4: 6978720705 | NO4: 8409773451 | NP4: 2849113880 | NQ4: 8901929192 | NR4: 8539135251 | NS4: 8829018125 | NW4: HMGPXL | NX4: =SUM(S4:AW4) -> 154157676741 | NY4: =SUM(AX4:BY4) -> 173596984879 | NZ4: =SUM(BZ4:DD4) -> 213619803644 | OA4: =SUM(DE4:EH4) -> 192385597636 | OB4: =SUM(EI4:FM4) -> 204650015967 | OC4: =SUM(FN4:GQ4) -> 201739115263 | OD4: =SUM(GR4:HV4) -> 221880214355 | OE4: =SUM(HW4:JA4) -> 210359474445 | OF4: =SUM(JB4:KE4) -> 210535471409 | OG4: =SUM(KF4:LJ4) -> 238740614465 | OH4: =SUM(LK4:MN4) -> 219783320450 | OI4: =SUM(MO4:NS4) -> 233011113141 | OJ4: =SUM(NX4:OI4) -> 2474459402395 | OK4: =NX4+NY4+NZ4 -> 541374465264 | OL4: =OA4+OB4+OC4 -> 598774728866 | OM4: =OD4+OE4+OF4 -> 642775160209 | ON4: =OG4+OH4+OI4 -> 691535048056 | OP4: 1854671422 | OQ4: 7405821310 | OR4: 6174701784 | OS4: 2271161796 | OT4: 8799817474 | OU4: 8093886298 | OV4: 8302035505 | OW4: 6808303550 | OX4: 7621714082 | OY4: 8976842505 | OZ4: 2862800002 | PA4: 8442736718 | PB4: 8185641401 | PC4: 7431454830 | PD4: 7210662770 | PE4: 7738193627 | PF4: 8026203367 | PG4: 2434982855 | PH4: 5494174111
B5: B2B | C5: CHC | D5: =P23 -> 445 | E5: =P19 -> 0 | F5: =P31 -> 330 | G5: =P27 -> 0 | H5: =P39 -> 0 | I5: =P35 -> 0 | J5: =SUM(D5:I5) -> 775 | L5: =M5/N5 -> 0.45615864 | M5: =E4/10^3 -> 0.90419 | N5: =SUM(OP5:PT5)/10^9 -> 1.9821832 | O5: =(Q5*1000-N5)/(31-DAY(TODAY())) -> 783.82616 | P5: HMGPXL | Q5: 8.6240699 | R5: =N5/Q5 -> 0.22984313 | S5: 25670 | T5: 206074549 | U5: 306438387 | V5: 189925693 | W5: 24967 | X5: 129275096 | Y5: 180152637 | Z5: 125659225 | AA5: 139163969 | AB5: 228949097 | AC5: 198545359 | AD5: 24983 | AE5: 110317174 | AF5: 131456877 | AG5: 177160210 | AH5: 137161634 | AI5: 185620837 | AJ5: 160995991 | AK5: 25438 | AL5: 132300012 | AM5: 176032945 | AN5: 162308941 | AO5: 99483108 | AP5: 100155099 | AQ5: 88744503 | AR5: 25778 | AS5: 25778 | AT5: 25778 | AU5: 25778 | AV5: 25778 | AW5: 25778 | AX5: 25778 | AY5: 25778 | AZ5: 183857311 | BA5: 110012928 | BB5: 127799652 | BC5: 260073345 | BD5: 162270922 | BE5: 240583896 | BF5: 26851 | BG5: 188151094 | BH5: 262283218 | BI5: 236305920 | BJ5: 206728895 | BK5: 311807851 | BL5: 221176152 | BM5: 26162 | BN5: 329756600 | BO5: 354755150 | BP5: 302007866 | BQ5: 179858932 | BR5: 193747129 | BS5: 169773478 | BT5: 27389 | BU5: 297962803 | BV5: 199274038 | BW5: 167839444 | BX5: 191358435 | BY5: 116924103 | BZ5: 105238296 | CA5: 28296 | CB5: 204394394 | CC5: 279543188 | CD5: 304877236 | CE5: 183842341 | CF5: 180691490 | CG5: 179486158 | CH5: 27260 | CI5: 235627117 | CJ5: 270079987 | CK5: 167829044 | CL5: 132824258 | CM5: 197043656 | CN5: 215543611 | CO5: 8396 | CP5: 172707629 | CQ5: 168856886 | CR5: 247428914 | CS5: 230536466 | CT5: 235447462 | CU5: 247836226 | CV5: 9544 | CW5: 162651841 | CX5: 247248126 | CY5: 202838310 | CZ5: 170493318 | DA5: 193546141 | DB5: 243060523 | DC5: 10528 | DD5: 267228369 | DE5: 297768932 | DF5: 81682595 | DG5: 179380158 | DH5: 174598707 | DI5: 187555373 | DJ5: 4211 | DK5: 4211 | DL5: 259347476 | DM5: 260943795 | DN5: 285186172 | DO5: 157710498 | DP5: 177230426 | DQ5: 5304 | DR5: 238495904 | DS5: 256427129 | DT5: 125418053 | DU5: 165022477 | DV5: 208089714 | DW5: 239933837 | DX5: 0 | DY5: 100955322 | DZ5: 203774521 | EA5: 198618466 | EB5: 143818624 | EC5: 144372022 | ED5: 106580247 | EE5: 0 | EF5: 223141853 | EG5: 103681681 | EH5: 0 | EI5: 0 | EJ5: 176527166 | EK5: 110585470 | EL5: 0 | EM5: 266661881 | EN5: 247777027 | EO5: 215467465 | EP5: 237158166 | EQ5: 196160428 | ER5: 117304543 | ES5: 0 | ET5: 173759814 | EU5: 167824360 | EV5: 115228410 | EW5: 221742117 | EX5: 105219111 | EY5: 156641630 | EZ5: 7422 | FA5: 219447192 | FB5: 181431908 | FC5: 142505967 | FD5: 120052640 | FE5: 138459102 | FF5: 138102103 | FG5: 8215 | FH5: 197209072 | FI5: 149298879 | FJ5: 85808668 | FK5: 155645719 | FL5: 120770881 | FM5: 87179219 | FN5: 0 | FO5: 203659609 | FP5: 215978994 | FQ5: 177550447 | FR5: 154512079 | FS5: 136073166 | FT5: 270860005 | FU5: 0 | FV5: 167166353 | FW5: 248376586 | FX5: 118517431 | FY5: 159506824 | FZ5: 185462826 | GA5: 202796572 | GB5: 0 | GC5: 149108242 | GD5: 237967946 | GE5: 115678666 | GF5: 187178748 | GG5: 228264579 | GH5: 143177430 | GI5: 0 | GJ5: 199801156 | GK5: 188762368 | GL5: 222799544 | GM5: 147527017 | GN5: 149995271 | GO5: 185660206 | GP5: 0 | GQ5: 99617749 | GR5: 225618510 | GS5: 104650380 | GT5: 167075997 | GU5: 145172688 | GV5: 186948372 | GW5: 0 | GX5: 259925151 | GY5: 241652412 | GZ5: 281772530 | HA5: 225133017 | HB5: 276088566 | HC5: 105869306 | HD5: 0 | HE5: 217164398 | HF5: 333535447 | HG5: 143936837 | HH5: 206057936 | HI5: 151950671 | HJ5: 157424883 | HK5: 0 | HL5: 255679037 | HM5: 250131839 | HN5: 215704617 | HO5: 211903562 | HP5: 230739812 | HQ5: 127357739 | HR5: 0 | HS5: 215939932 | HT5: 196057844 | HU5: 253201266 | HV5: 197450261 | HW5: 197340081 | HX5: 206753420 | HY5: 0 | HZ5: 192502272 | IA5: 281009721 | IB5: 195900666 | IC5: 193253111 | ID5: 200495293 | IE5: 89491240 | IF5: 0 | IG5: 165395556 | IH5: 212676273 | II5: 169738938 | IJ5: 149726669 | IK5: 128178234 | IL5: 201709499 | IM5: 0 | IN5: 214434132 | IO5: 136286551 | IP5: 180820386 | IQ5: 151602684 | IR5: 199698742 | IS5: 98421949 | IT5: 0 | IU5: 231614046 | IV5: 123610711 | IW5: 129527474 | IX5: 209026167 | IY5: 134752576 | IZ5: 149333530 | JA5: 0 | JB5: 7183802 | JC5: 0 | JD5: 276763223 | JE5: 278101050 | JF5: 175066589 | JG5: 133221165 | JH5: 0 | JI5: 184651852 | JJ5: 188568544 | JK5: 159840421 | JL5: 165435263 | JM5: 161463678 | JN5: 228311376 | JO5: 0 | JP5: 220320775 | JQ5: 195861376 | JR5: 163667804 | JS5: 97349823 | JT5: 146768916 | JU5: 99989840 | JV5: 0 | JW5: 185883086 | JX5: 158824147 | JY5: 102783809 | JZ5: 193835329 | KA5: 83207612 | KB5: 148754215 | KC5: 5465 | KD5: 163968483 | KE5: 167495675 | KF5: 102014594 | KG5: 127159575 | KH5: 144164739 | KI5: 127238315 | KJ5: 6065 | KK5: 240315378 | KL5: 210008248 | KM5: 69264267 | KN5: 145126521 | KO5: 125207862 | KP5: 115322468 | KQ5: 4492 | KR5: 194971076 | KS5: 196825271 | KT5: 118266775 | KU5: 174312837 | KV5: 192027816 | KW5: 124119886 | KX5: 5306 | KY5: 99142335 | KZ5: 233616357 | LA5: 135861722 | LB5: 115127741 | LC5: 129095108 | LD5: 176597868 | LE5: 6163 | LF5: 174439258 | LG5: 63853767 | LH5: 93439003 | LI5: 118916913 | LJ5: 118854496 | LK5: 86620721 | LL5: 6719 | LM5: 120129211 | LN5: 169520127 | LO5: 188379182 | LP5: 83479389 | LQ5: 75593930 | LR5: 104995483 | LS5: 5023 | LT5: 144427881 | LU5: 137567940 | LV5: 67679597 | LW5: 158242347 | LX5: 103489939 | LY5: 164421548 | LZ5: 5548 | MA5: 248739951 | MB5: 100792945 | MC5: 73638451 | MD5: 141237644 | ME5: 78618186 | MF5: 56877447 | MG5: 6197 | MH5: 120644363 | MI5: 107731574 | MJ5: 115606598 | MK5: 96919835 | ML5: 79630676 | MM5: 59731191 | MN5: 6768 | MO5: 262132784 | MP5: 208863860 | MQ5: 161706200 | MR5: 206220382 | MS5: 121857653 | MT5: 93144039 | MU5: 0 | MV5: 158310261 | MW5: 118937700 | MX5: 146597109 | MY5: 113946282 | MZ5: 179255618 | NA5: 146339600 | NB5: 0 | NC5: 193072933 | ND5: 201266055 | NE5: 166086446 | NF5: 174838058 | NG5: 242024970 | NH5: 235371496 | NI5: 125201829 | NJ5: 336021288 | NK5: 134524250 | NL5: 111051892 | NM5: 89555941 | NN5: 36254683 | NO5: 72414861 | NP5: 7081 | NQ5: 184578711 | NR5: 217812105 | NS5: 88182369 | NW5: HMTD | NX5: =SUM(S5:AW5) -> 3366177069 | NY5: =SUM(AX5:BY5) -> 5014441120 | NZ5: =SUM(BZ5:DD5) -> 5446985011 | OA5: =SUM(DE5:EH5) -> 4519747708 | OB5: =SUM(EI5:FM5) -> 4243984575 | OC5: =SUM(FN5:GQ5) -> 4495999814 | OD5: =SUM(GR5:HV5) -> 5584143010 | OE5: =SUM(HW5:JA5) -> 4543299921 | OF5: =SUM(JB5:KE5) -> 4087323318 | OG5: =SUM(KF5:LJ5) -> 3865312222 | OH5: =SUM(LK5:MN5) -> 2884746411 | OI5: =SUM(MO5:NS5) -> 4525576456 | OJ5: =SUM(NX5:OI5) -> 52577736635 | OK5: =NX5+NY5+NZ5 -> 13827603200 | OL5: =OA5+OB5+OC5 -> 13259732097 | OM5: =OD5+OE5+OF5 -> 14214766249 | ON5: =OG5+OH5+OI5 -> 11275635089 | OQ5: 101203131 | OR5: 69355503 | OT5: 121336101 | OU5: 195093750 | OV5: 169221986 | OW5: 122004718 | OX5: 75668487 | OY5: 179826451 | PA5: 121769517 | PB5: 231254163 | PC5: 105998750 | PD5: 137006701 | PE5: 109761391 | PF5: 122015067 | PH5: 120667514
C6: REF | D6: =P24 -> 355 | E6: =P20 -> 19.12 | F6: =P32 -> 2921 | G6: =P28 -> 2712 | H6: =P40 -> 0 | I6: =P36 -> 0 | J6: =SUM(D6:I6) -> 6007.12 | L6: =M6/N6 -> 0.094218112 | M6: =D4/10^3 -> 2.27 | N6: =SUM(OP6:PT6)/10^9 -> 24.093032 | O6: =(Q6*1000-N6)/(31-DAY(TODAY())) -> 4497.2233 | P6: HMTD | Q6: 49.493549 | R6: =N6/Q6 -> 0.48679136 | S6: 440155304 | T6: 1206281973 | U6: 1043485963 | V6: 1001630757 | W6: 697723412 | X6: 1196738788 | Y6: 1149681295 | Z6: 1182113974 | AA6: 957963988 | AB6: 1151017728 | AC6: 1426044369 | AD6: 628375755 | AE6: 1069187650 | AF6: 848752603 | AG6: 955304429 | AH6: 893356419 | AI6: 974948862 | AJ6: 1056510244 | AK6: 686762178 | AL6: 1121322072 | AM6: 951589647 | AN6: 968811588 | AO6: 1011770446 | AP6: 897131205 | AQ6: 1188400000 | AR6: 600916939 | AS6: 839132533 | AT6: 584333466 | AU6: 119254004 | AV6: 273586919 | AW6: 413648485 | AX6: 373285978 | AY6: 122443489 | AZ6: 1141361332 | BA6: 911145795 | BB6: 950472634 | BC6: 881722675 | BD6: 1268922191 | BE6: 1339097915 | BF6: 485485780 | BG6: 1457435344 | BH6: 1036680647 | BI6: 1081299128 | BJ6: 1030091718 | BK6: 1178632419 | BL6: 1410775136 | BM6: 720173743 | BN6: 1618640911 | BO6: 1618852211 | BP6: 1234948279 | BQ6: 1341741604 | BR6: 1133112955 | BS6: 1704104231 | BT6: 630135552 | BU6: 1531082128 | BV6: 1327932414 | BW6: 1184552383 | BX6: 1022100152 | BY6: 998515712 | BZ6: 1436504471 | CA6: 755797032 | CB6: 1231121754 | CC6: 1476741974 | CD6: 1338380320 | CE6: 1199196130 | CF6: 1686428757 | CG6: 1456358832 | CH6: 660303688 | CI6: 1270889239 | CJ6: 1357778472 | CK6: 1444806114 | CL6: 1298658587 | CM6: 1168660162 | CN6: 1604169677 | CO6: 592185364 | CP6: 1305070327 | CQ6: 1145669451 | CR6: 1413578909 | CS6: 1068345149 | CT6: 1238613606 | CU6: 1544518796 | CV6: 811907515 | CW6: 1405615621 | CX6: 1165839987 | CY6: 1346241219 | CZ6: 1220908188 | DA6: 1555246444 | DB6: 1715150921 | DC6: 482092137 | DD6: 1572337568 | DE6: 1128222248 | DF6: 1336202654 | DG6: 1205323077 | DH6: 1202342348 | DI6: 1480693683 | DJ6: 729880343 | DK6: 478991516 | DL6: 1355109265 | DM6: 1330072490 | DN6: 1259611805 | DO6: 1234223951 | DP6: 1508827801 | DQ6: 604036668 | DR6: 1255702881 | DS6: 1030637967 | DT6: 1156402367 | DU6: 1358232748 | DV6: 1348296007 | DW6: 1712854533 | DX6: 642057198 | DY6: 1287285224 | DZ6: 1281781983 | EA6: 1000272381 | EB6: 1323309640 | EC6: 1230345012 | ED6: 1115938376 | EE6: 602454398 | EF6: 1171033447 | EG6: 1418067530 | EH6: 418432226 | EI6: 356844012 | EJ6: 1143322243 | EK6: 1118195109 | EL6: 936617012 | EM6: 1223340882 | EN6: 1261908943 | EO6: 1093158547 | EP6: 1003356014 | EQ6: 1769475018 | ER6: 1304028049 | ES6: 635112837 | ET6: 1276374844 | EU6: 1202224909 | EV6: 1292571660 | EW6: 1278571660 | EX6: 1407171660 | EY6: 1287300000 | EZ6: 482407442 | FA6: 1334405871 | FB6: 1347140075 | FC6: 1398348286 | FD6: 1008741654 | FE6: 1243206762 | FF6: 1440649661 | FG6: 574078635 | FH6: 1376475704 | FI6: 1294168734 | FJ6: 1214902363 | FK6: 1312771660 | FL6: 1162571660 | FM6: 1277000000 | FN6: 721000000 | FO6: 1000715637 | FP6: 992012833 | FQ6: 1470803404 | FR6: 1179873772 | FS6: 1149747988 | FT6: 1596107377 | FU6: 482833855 | FV6: 1345923764 | FW6: 1539915318 | FX6: 1147295026 | FY6: 1314245351 | FZ6: 1587895026 | GA6: 1222000000 | GB6: 455000000 | GC6: 1355195026 | GD6: 1377495026 | GE6: 1396001793 | GF6: 1279769177 | GG6: 1437669954 | GH6: 1427488907 | GI6: 764145177 | GJ6: 1277675574 | GK6: 1597537326 | GL6: 1382026694 | GM6: 1193338140 | GN6: 954487748 | GO6: 1242361052 | GP6: 868257717 | GQ6: 1488065928 | GR6: 1453255905 | GS6: 1215798866 | GT6: 1098598351 | GU6: 1193588012 | GV6: 1407587093 | GW6: 797691986 | GX6: 1691939615 | GY6: 1454805871 | GZ6: 1243353570 | HA6: 1432152194 | HB6: 1504378217 | HC6: 1930032894 | HD6: 809982599 | HE6: 1786843226 | HF6: 1684140522 | HG6: 1457933965 | HH6: 1577193937 | HI6: 1351119972 | HJ6: 1658132137 | HK6: 528398618 | HL6: 1379508062 | HM6: 1391617738 | HN6: 1357117932 | HO6: 1255302427 | HP6: 1459668080 | HQ6: 1414644432 | HR6: 865579282 | HS6: 1410613901 | HT6: 1495191801 | HU6: 1454731887 | HV6: 1133866075 | HW6: 1589733368 | HX6: 1681735201 | HY6: 1127942545 | HZ6: 1537779054 | IA6: 1652993546 | IB6: 1718896262 | IC6: 1330315250 | ID6: 1638853731 | IE6: 1616515002 | IF6: 785060798 | IG6: 1620005014 | IH6: 1561679951 | II6: 1380491348 | IJ6: 1508285556 | IK6: 1408876831 | IL6: 1480620722 | IM6: 665832302 | IN6: 1808729546 | IO6: 1259362424 | IP6: 1492851065 | IQ6: 1027984356 | IR6: 1570442847 | IS6: 1489546404 | IT6: 807679210 | IU6: 1688249325 | IV6: 1375955603 | IW6: 1640001766 | IX6: 1311847797 | IY6: 1382632016 | IZ6: 1465000000 | JA6: 597000000 | JB6: 1424311770 | JC6: 563409521 | JD6: 511597125 | JE6: 1621305151 | JF6: 1560560629 | JG6: 1492588111 | JH6: 709454780 | JI6: 1261080214 | JJ6: 1384139331 | JK6: 1248235115 | JL6: 1317586235 | JM6: 1325747653 | JN6: 1701450071 | JO6: 733519659 | JP6: 1236276509 | JQ6: 1460547149 | JR6: 1330418520 | JS6: 1182801807 | JT6: 1265459707 | JU6: 1661712297 | JV6: 852723120 | JW6: 1551369839 | JX6: 1370376252 | JY6: 1499311770 | JZ6: 1183504500 | KA6: 1595803030 | KB6: 1870022882 | KC6: 720469440 | KD6: 1469407092 | KE6: 1562383459 | KF6: 1609162429 | KG6: 1708162429 | KH6: 1242821033 | KI6: 1703823715 | KJ6: 1097109920 | KK6: 2333735069 | KL6: 1436592995 | KM6: 1660579644 | KN6: 1731223561 | KO6: 1585546058 | KP6: 1952668434 | KQ6: 883228275 | KR6: 1777637866 | KS6: 1609595523 | KT6: 1807266012 | KU6: 1430538687 | KV6: 1725318380 | KW6: 2036944584 | KX6: 730029136 | KY6: 1395161714 | KZ6: 1561635147 | LA6: 1499935617 | LB6: 1742956953 | LC6: 1430450675 | LD6: 1844567465 | LE6: 917192143 | LF6: 1431909377 | LG6: 1429091529 | LH6: 1717876204 | LI6: 1783336774 | LJ6: 1580813985 | LK6: 2066100680 | LL6: 931604564 | LM6: 1360393680 | LN6: 1542672467 | LO6: 1481555840 | LP6: 1389304118 | LQ6: 1439673462 | LR6: 1872265821 | LS6: 744929273 | LT6: 1473979675 | LU6: 1926597366 | LV6: 1273747376 | LW6: 1200274940 | LX6: 1511659476 | LY6: 1774519170 | LZ6: 728977257 | MA6: 1714288827 | MB6: 1692443895 | MC6: 1348190893 | MD6: 1172078957 | ME6: 1508591045 | MF6: 1772141555 | MG6: 742127723 | MH6: 1632548116 | MI6: 1298340018 | MJ6: 1409226104 | MK6: 1461848634 | ML6: 1443490199 | MM6: 1573372626 | MN6: 859437842 | MO6: 1440006188 | MP6: 1827687856 | MQ6: 1233057835 | MR6: 1546089086 | MS6: 1521492569 | MT6: 1740865212 | MU6: 689474126 | MV6: 1698755504 | MW6: 1612742803 | MX6: 1999263387 | MY6: 1554222134 | MZ6: 1396546770 | NA6: 1623292122 | NB6: 797589359 | NC6: 1522124639 | ND6: 1453703275 | NE6: 1684681439 | NF6: 1434741542 | NG6: 1334102594 | NH6: 1531037856 | NI6: 709269147 | NJ6: 1595726665 | NK6: 1365644813 | NL6: 1303789089 | NM6: 1545980978 | NN6: 1467453890 | NO6: 1474595188 | NP6: 640463785 | NQ6: 1417479535 | NR6: 1780109711 | NS6: 1263433305 | NW6: HMGKD | NX6: =SUM(S6:AW6) -> 27535932995 | NY6: =SUM(AX6:BY6) -> 30734744456 | NZ6: =SUM(BZ6:DD6) -> 38969116411 | OA6: =SUM(DE6:EH6) -> 34206641767 | OB6: =SUM(EI6:FM6) -> 36056441906 | OC6: =SUM(FN6:GQ6) -> 36246884590 | OD6: =SUM(GR6:HV6) -> 41894769167 | OE6: =SUM(HW6:JA6) -> 43222898840 | OF6: =SUM(JB6:KE6) -> 38667572738 | OG6: =SUM(KF6:LJ6) -> 48396911333 | OH6: =SUM(LK6:MN6) -> 42346381599 | OI6: =SUM(MO6:NS6) -> 44205422402 | OJ6: =SUM(NX6:OI6) -> 462483718204 | OK6: =NX6+NY6+NZ6 -> 97239793862 | OL6: =OA6+OB6+OC6 -> 106509968263 | OM6: =OD6+OE6+OF6 -> 123785240745 | ON6: =OG6+OH6+OI6 -> 134948715334 | OP6: 562779688 | OQ6: 1555102280 | OR6: 1293003605 | OS6: 734776436 | OT6: 1482691932 | OU6: 1286390851 | OV6: 1404954793 | OW6: 1263701899 | OX6: 1363106874 | OY6: 1485079740 | OZ6: 915727708 | PA6: 1728036816 | PB6: 1588171759 | PC6: 1356661215 | PD6: 1438352299 | PE6: 1555968420 | PF6: 1407618430 | PG6: 643189663 | PH6: 1027717835
B7: B2C | C7: Organic | D7: =P25 -> 1470 | E7: =P21 -> 885.07 | F7: =P33 -> 1268 | G7: =P29 -> 3283 | H7: =P41 -> 343 | I7: =P37 -> 0 | J7: =SUM(D7:I7) -> 7249.07 | L7: =M7/N7 -> 0 | M7: =I4/10^3 -> 0 | N7: =SUM(OP7:PT7)/10^9 -> 0.92378009 | O7: =(Q7*1000-N7)/(31-DAY(TODAY())) -> 628.31002 | P7: HMGKD | Q7: 6.912334 | R7: =N7/Q7 -> 0.13364228 | S7: 0 | T7: 207826005 | U7: 102569142 | V7: 129389304 | W7: 3292903 | X7: 53546447 | Y7: 74214732 | Z7: 129029501 | AA7: 172984133 | AB7: 139326300 | AC7: 211620120 | AD7: 1691941 | AE7: 66380381 | AF7: 87152030 | AG7: 222648773 | AH7: 163525660 | AI7: 113225735 | AJ7: 180624631 | AK7: 1810192 | AL7: 96264572 | AM7: 105129239 | AN7: 154964399 | AO7: 84191618 | AP7: 176069873 | AQ7: 35252809 | AR7: 3728890 | AS7: 0 | AT7: 0 | AU7: 0 | AV7: 0 | AW7: 0 | AX7: 0 | AY7: 0 | AZ7: 29722263 | BA7: 30177362 | BB7: 39228706 | BC7: 160189122 | BD7: 195206253 | BE7: 279321017 | BF7: 2046690 | BG7: 129562488 | BH7: 150949357 | BI7: 221092500 | BJ7: 139366888 | BK7: 105591636 | BL7: 146242651 | BM7: 3918760 | BN7: 82780022 | BO7: 126433168 | BP7: 132319207 | BQ7: 79180632 | BR7: 102493231 | BS7: 238886507 | BT7: 2347254 | BU7: 131354817 | BV7: 139392745 | BW7: 165774699 | BX7: 164858490 | BY7: 357688349 | BZ7: 142495381 | CA7: 5509733 | CB7: 142721949 | CC7: 129222245 | CD7: 178239646 | CE7: 104288265 | CF7: 87005540 | CG7: 149508536 | CH7: 3562613 | CI7: 275298690 | CJ7: 161122332 | CK7: 181516095 | CL7: 121525466 | CM7: 220727536 | CN7: 218470378 | CO7: 4902578 | CP7: 182199538 | CQ7: 139975585 | CR7: 145840754 | CS7: 97299256 | CT7: 97382780 | CU7: 111629571 | CV7: 4798082 | CW7: 158547573 | CX7: 84972610 | CY7: 109803120 | CZ7: 85823937 | DA7: 174632257 | DB7: 137161992 | DC7: 2447721 | DD7: 298318019 | DE7: 175650853 | DF7: 91482630 | DG7: 191571350 | DH7: 179171550 | DI7: 255598522 | DJ7: 2110872 | DK7: 0 | DL7: 145014570 | DM7: 209911418 | DN7: 122648205 | DO7: 164848255 | DP7: 139995383 | DQ7: 1709036 | DR7: 81136838 | DS7: 197310017 | DT7: 109269535 | DU7: 152884654 | DV7: 121412257 | DW7: 224749504 | DX7: 2801078 | DY7: 81184362 | DZ7: 128963798 | EA7: 162544870 | EB7: 163617758 | EC7: 103438812 | ED7: 157319068 | EE7: 0 | EF7: 201130385 | EG7: 144331390 | EH7: 0 | EI7: 0 | EJ7: 70132166 | EK7: 62062928 | EL7: 0 | EM7: 98734585 | EN7: 87463542 | EO7: 107401785 | EP7: 113010280 | EQ7: 78344541 | ER7: 106273077 | ES7: 0 | ET7: 170782548 | EU7: 102488443 | EV7: 134520819 | EW7: 179132580 | EX7: 208663664 | EY7: 56856676 | EZ7: 0 | FA7: 77111604 | FB7: 214964695 | FC7: 107755423 | FD7: 52240931 | FE7: 105721486 | FF7: 44893785 | FG7: 0 | FH7: 61236549 | FI7: 126425045 | FJ7: 70859611 | FK7: 153424243 | FL7: 57302056 | FM7: 87047009 | FN7: 0 | FO7: 143572959 | FP7: 120040888 | FQ7: 259552435 | FR7: 113028479 | FS7: 154894948 | FT7: 179592623 | FU7: 0 | FV7: 82084840 | FW7: 84139448 | FX7: 109087375 | FY7: 190099542 | FZ7: 63518887 | GA7: 170956844 | GB7: 0 | GC7: 90324015 | GD7: 126315266 | GE7: 172458559 | GF7: 220407493 | GG7: 45895627 | GH7: 167502304 | GI7: 0 | GJ7: 241215298 | GK7: 234260165 | GL7: 175744421 | GM7: 135660421 | GN7: 153813378 | GO7: 180662387 | GP7: 0 | GQ7: 152754601 | GR7: 121640150 | GS7: 111675714 | GT7: 60348715 | GU7: 57908201 | GV7: 85888065 | GW7: 0 | GX7: 112780433 | GY7: 88306839 | GZ7: 54373666 | HA7: 116133556 | HB7: 110868345 | HC7: 142549709 | HD7: 0 | HE7: 141775231 | HF7: 165836352 | HG7: 91620814 | HH7: 150299946 | HI7: 155507212 | HJ7: 199720620 | HK7: 0 | HL7: 186631236 | HM7: 136815942 | HN7: 156540446 | HO7: 272472055 | HP7: 139897735 | HQ7: 123699265 | HR7: 0 | HS7: 183236324 | HT7: 81606853 | HU7: 283808787 | HV7: 138838635 | HW7: 215497891 | HX7: 131272640 | HY7: 0 | HZ7: 149629852 | IA7: 166408851 | IB7: 163898130 | IC7: 55559055 | ID7: 86958209 | IE7: 110890115 | IF7: 0 | IG7: 196496132 | IH7: 166581818 | II7: 98649055 | IJ7: 114214015 | IK7: 288153192 | IL7: 122535922 | IM7: 0 | IN7: 96430070 | IO7: 168273913 | IP7: 95249468 | IQ7: 90002148 | IR7: 95215582 | IS7: 110851583 | IT7: 0 | IU7: 87485109 | IV7: 148461597 | IW7: 32901530 | IX7: 69550693 | IY7: 92656337 | IZ7: 250541754 | JA7: 0 | JB7: 0 | JC7: 0 | JD7: 74386228 | JE7: 72603263 | JF7: 130668490 | JG7: 130989354 | JH7: 0 | JI7: 65170465 | JJ7: 45140696 | JK7: 66180420 | JL7: 92619050 | JM7: 90242040 | JN7: 85785427 | JO7: 0 | JP7: 87598142 | JQ7: 109664615 | JR7: 92160970 | JS7: 62974122 | JT7: 52812126 | JU7: 74944163 | JV7: 0 | JW7: 55240108 | JX7: 104294112 | JY7: 89548201 | JZ7: 62037376 | KA7: 194753739 | KB7: 144711053 | KC7: 0 | KD7: 62808581 | KE7: 129014572 | KF7: 71876565 | KG7: 44782059 | KH7: 86116550 | KI7: 125755776 | KJ7: 0 | KK7: 153565793 | KL7: 67191658 | KM7: 165932826 | KN7: 78621612 | KO7: 47885145 | KP7: 98338932 | KQ7: 0 | KR7: 97268400 | KS7: 84397439 | KT7: 51954450 | KU7: 91377272 | KV7: 151291063 | KW7: 178280892 | KX7: 0 | KY7: 85240389 | KZ7: 79005627 | LA7: 105062028 | LB7: 44745209 | LC7: 194397537 | LD7: 122928718 | LE7: 0 | LF7: 72083324 | LG7: 76088908 | LH7: 43224872 | LI7: 69119081 | LJ7: 127443714 | LK7: 179019118 | LL7: 0 | LM7: 32672953 | LN7: 100674265 | LO7: 96217529 | LP7: 99178875 | LQ7: 74856531 | LR7: 142918470 | LS7: 0 | LT7: 93875771 | LU7: 76226792 | LV7: 40723631 | LW7: 53725489 | LX7: 58378554 | LY7: 68551319 | LZ7: 0 | MA7: 114671931 | MB7: 145388610 | MC7: 167041709 | MD7: 38114225 | ME7: 90629495 | MF7: 263257838 | MG7: 0 | MH7: 63102296 | MI7: 196104443 | MJ7: 37122420 | MK7: 88832154 | ML7: 124371771 | MM7: 57884411 | MN7: 0 | MO7: 112035774 | MP7: 169249502 | MQ7: 53500319 | MR7: 78918654 | MS7: 100602428 | MT7: 53942415 | MU7: 0 | MV7: 107448319 | MW7: 84921615 | MX7: 67105016 | MY7: 75808356 | MZ7: 79768456 | NA7: 83370167 | NB7: 0 | NC7: 133559638 | ND7: 85042949 | NE7: 28617946 | NF7: 142422002 | NG7: 112097804 | NH7: 102120372 | NI7: 0 | NJ7: 123549037 | NK7: 89100023 | NL7: 88379194 | NM7: 115694875 | NN7: 55437442 | NO7: 88838970 | NP7: 0 | NQ7: 146642022 | NR7: 72074362 | NS7: 36472631 | NW7: HPEC | NX7: =SUM(S7:AW7) -> 2716459330 | NY7: =SUM(AX7:BY7) -> 3356124814 | NZ7: =SUM(BZ7:DD7) -> 3956949778 | OA7: =SUM(DE7:EH7) -> 3711806970 | OB7: =SUM(EI7:FM7) -> 2734850071 | OC7: =SUM(FN7:GQ7) -> 3767583203 | OD7: =SUM(GR7:HV7) -> 3670780846 | OE7: =SUM(HW7:JA7) -> 3404364661 | OF7: =SUM(JB7:KE7) -> 2176347313 | OG7: =SUM(KF7:LJ7) -> 2613975839 | OH7: =SUM(LK7:MN7) -> 2503540600 | OI7: =SUM(MO7:NS7) -> 2486720288 | OJ7: =SUM(NX7:OI7) -> 37099503713 | OK7: =NX7+NY7+NZ7 -> 10029533922 | OL7: =OA7+OB7+OC7 -> 10214240244 | OM7: =OD7+OE7+OF7 -> 9251492820 | ON7: =OG7+OH7+OI7 -> 7604236727 | OQ7: 68860066 | OR7: 54240221 | OT7: 37305716 | OU7: 131248361 | OV7: 95576409 | OW7: 13792087 | OX7: 91098506 | OY7: 39824005 | PA7: 29187045 | PB7: 36178171 | PC7: 57360411 | PD7: 52347721 | PE7: 35276613 | PF7: 107015259 | PH7: 74469499
B8: B2C | C8: Ads | J8: =SUM(D8:I8) -> 0 | L8: =M8/N8 -> 6.86 | M8: =P41/10^3 -> 0.343 | N8: =SUM(OP8:PT8)/10^9 -> 0.05 | O8: =(Q8*1000-N8)/(31-DAY(TODAY())) -> 557.51424 | P8: HPEC | Q8: 6.1327066 | R8: =N8/Q8 -> 0.008153007 | S8: 0 | T8: 116903792 | U8: 94369364 | V8: 227411308 | W8: 33388365 | X8: 127088905 | Y8: 187585734 | Z8: 147159058 | AA8: 123630315 | AB8: 134627219 | AC8: 244672800 | AD8: 43743627 | AE8: 214966232 | AF8: 168356515 | AG8: 149309483 | AH8: 79773678 | AI8: 152709920 | AJ8: 259876737 | AK8: 37963913 | AL8: 132100990 | AM8: 207238819 | AN8: 162914691 | AO8: 154311088 | AP8: 146444919 | AQ8: 133493445 | AR8: 0 | AS8: 0 | AT8: 0 | AU8: 0 | AV8: 0 | AW8: 0 | AX8: 0 | AY8: 0 | AZ8: 97303348 | BA8: 188216903 | BB8: 122565281 | BC8: 61616143 | BD8: 261774616 | BE8: 351726309 | BF8: 71867905 | BG8: 141072951 | BH8: 269355878 | BI8: 224404097 | BJ8: 139977313 | BK8: 243737364 | BL8: 356646509 | BM8: 30019921 | BN8: 232582160 | BO8: 188389944 | BP8: 156757377 | BQ8: 149151618 | BR8: 163589716 | BS8: 289221939 | BT8: 52406567 | BU8: 201415256 | BV8: 203277826 | BW8: 139895217 | BX8: 111469124 | BY8: 161568841 | BZ8: 275725605 | CA8: 49511213 | CB8: 142690057 | CC8: 177561708 | CD8: 122147127 | CE8: 152813803 | CF8: 122996360 | CG8: 391835658 | CH8: 34560661 | CI8: 155554812 | CJ8: 202856013 | CK8: 229585359 | CL8: 108769323 | CM8: 161892207 | CN8: 279709520 | CO8: 43232730 | CP8: 162277039 | CQ8: 146229873 | CR8: 149501872 | CS8: 162721610 | CT8: 189649280 | CU8: 240112278 | CV8: 65463234 | CW8: 173648326 | CX8: 197628689 | CY8: 83074511 | CZ8: 176067224 | DA8: 246275786 | DB8: 228598960 | DC8: 32786813 | DD8: 192729644 | DE8: 203232538 | DF8: 113459937 | DG8: 113110375 | DH8: 289970593 | DI8: 215014468 | DJ8: 30768967 | DK8: 0 | DL8: 178695704 | DM8: 147920727 | DN8: 133747664 | DO8: 136064718 | DP8: 296115749 | DQ8: 37536841 | DR8: 136000980 | DS8: 184239654 | DT8: 190207471 | DU8: 172777965 | DV8: 199592658 | DW8: 275138951 | DX8: 40142199 | DY8: 187152062 | DZ8: 209086587 | EA8: 199388340 | EB8: 170299641 | EC8: 140794389 | ED8: 205817791 | EE8: 31671019 | EF8: 124726458 | EG8: 157220875 | EH8: 0 | EI8: 0 | EJ8: 116016455 | EK8: 216379523 | EL8: 63085473 | EM8: 192650767 | EN8: 206157391 | EO8: 119022959 | EP8: 132138446 | EQ8: 127252204 | ER8: 227199417 | ES8: 48919704 | ET8: 179769207 | EU8: 295021062 | EV8: 141148674 | EW8: 133659378 | EX8: 221768246 | EY8: 310163716 | EZ8: 46487788 | FA8: 180929324 | FB8: 151407464 | FC8: 186398378 | FD8: 112635588 | FE8: 154494934 | FF8: 299246892 | FG8: 63436388 | FH8: 173623325 | FI8: 176317574 | FJ8: 139727606 | FK8: 145730408 | FL8: 183813143 | FM8: 300541955 | FN8: 40062105 | FO8: 249445599 | FP8: 194345211 | FQ8: 154791017 | FR8: 231350422 | FS8: 151066890 | FT8: 207082464 | FU8: 40002508 | FV8: 218740502 | FW8: 164576357 | FX8: 139847027 | FY8: 109917900 | FZ8: 177173256 | GA8: 244072017 | GB8: 60430469 | GC8: 154284597 | GD8: 234466625 | GE8: 135100720 | GF8: 160056474 | GG8: 179178236 | GH8: 293000963 | GI8: 58730407 | GJ8: 255066105 | GK8: 195854466 | GL8: 104960826 | GM8: 161049352 | GN8: 130222503 | GO8: 215974639 | GP8: 64123942 | GQ8: 159570884 | GR8: 161152254 | GS8: 134678922 | GT8: 118798944 | GU8: 139767633 | GV8: 256662337 | GW8: 62635577 | GX8: 163263725 | GY8: 203390887 | GZ8: 116487504 | HA8: 215718076 | HB8: 135692870 | HC8: 296811693 | HD8: 29382730 | HE8: 163593522 | HF8: 196301424 | HG8: 124504471 | HH8: 167197847 | HI8: 218918693 | HJ8: 207076959 | HK8: 76261510 | HL8: 144127762 | HM8: 173261934 | HN8: 149827553 | HO8: 167820819 | HP8: 152128140 | HQ8: 262767386 | HR8: 44479449 | HS8: 122227445 | HT8: 192252479 | HU8: 143056951 | HV8: 159137616 | HW8: 214077420 | HX8: 286573269 | HY8: 4596329 | HZ8: 192601842 | IA8: 201445505 | IB8: 224049325 | IC8: 208047240 | ID8: 174627045 | IE8: 120329946 | IF8: 36057170 | IG8: 195307891 | IH8: 204236745 | II8: 128691564 | IJ8: 128691564 | IK8: 128691564 | IL8: 0 | IM8: 0 | IN8: 128691564 | IO8: 128691564 | IP8: 128691564 | IQ8: 128691564 | IR8: 128691564 | IS8: 0 | IT8: 0 | IU8: 128691564 | IV8: 128691564 | IW8: 128691564 | IX8: 128691564 | IY8: 128691564 | IZ8: 0 | JA8: 0 | JB8: 227401627 | JC8: 0 | JD8: 0 | JE8: 227401627 | JF8: 227401627 | JG8: 0 | JH8: 0 | JI8: 227401627 | JJ8: 227401627 | JK8: 227401627 | JL8: 227401627 | JM8: 227401627 | JN8: 0 | JO8: 0 | JP8: 227401627 | JQ8: 227401627 | JR8: 227401627 | JS8: 227401627 | JT8: 227401627 | JU8: 0 | JV8: 0 | JW8: 227401627 | JX8: 227401627 | JY8: 227401627 | JZ8: 227401627 | KA8: 227401627 | KB8: 0 | KC8: 0 | KD8: 227401627 | KE8: 227401627 | KF8: 217713962 | KG8: 217713962 | KH8: 217713962 | KI8: 0 | KJ8: 0 | KK8: 217713962 | KL8: 217713962 | KM8: 217713962 | KN8: 217713962 | KO8: 217713962 | KP8: 0 | KQ8: 0 | KR8: 217713962 | KS8: 217713962 | KT8: 217713962 | KU8: 217713962 | KV8: 217713962 | KW8: 0 | KX8: 0 | KY8: 217713962 | KZ8: 217713962 | LA8: 217713962 | LB8: 217713962 | LC8: 217713962 | LD8: 0 | LE8: 0 | LF8: 217713962 | LG8: 217713962 | LH8: 217713962 | LI8: 217713962 | LJ8: 217713962 | LK8: 0 | LL8: 0 | LM8: 257172073 | LN8: 257172073 | LO8: 257172073 | LP8: 257172073 | LQ8: 257172073 | LR8: 0 | LS8: 0 | LT8: 257172073 | LU8: 257172073 | LV8: 257172073 | LW8: 257172073 | LX8: 257172073 | LY8: 0 | LZ8: 0 | MA8: 257172073 | MB8: 257172073 | MC8: 257172073 | MD8: 257172073 | ME8: 257172073 | MF8: 0 | MG8: 0 | MH8: 257172073 | MI8: 257172073 | MJ8: 257172073 | MK8: 257172073 | ML8: 257172073 | MM8: 0 | MN8: 0 | MO8: 0 | MP8: 0 | MQ8: 0 | MR8: 0 | MS8: 0 | MT8: 0 | MU8: 0 | MV8: 0 | MW8: 0 | MX8: 0 | MY8: 0 | MZ8: 0 | NA8: 0 | NB8: 0 | NC8: 0 | ND8: 0 | NE8: 0 | NF8: 0 | NG8: 0 | NH8: 0 | NI8: 0 | NJ8: 0 | NK8: 0 | NL8: 0 | NM8: 0 | NN8: 0 | NO8: 0 | NP8: 0 | NQ8: 0 | NR8: 0 | NS8: 0 | NW8: HPH | NX8: =SUM(S8:AW8) -> 3480040917 | NY8: =SUM(AX8:BY8) -> 4610010123 | NZ8: =SUM(BZ8:DD8) -> 5098207295 | OA8: =SUM(DE8:EH8) -> 4519895321 | OB8: =SUM(EI8:FM8) -> 5045143389 | OC8: =SUM(FN8:GQ8) -> 4884544483 | OD8: =SUM(GR8:HV8) -> 4899385112 | OE8: =SUM(HW8:JA8) -> 3734940059 | OF8: =SUM(JB8:KE8) -> 4548032540 | OG8: =SUM(KF8:LJ8) -> 5007421126 | OH8: =SUM(LK8:MN8) -> 5143441460 | OI8: =SUM(MO8:NS8) -> 0 | OJ8: =SUM(NX8:OI8) -> 50971061825 | OK8: =NX8+NY8+NZ8 -> 13188258335 | OL8: =OA8+OB8+OC8 -> 14449583193 | OM8: =OD8+OE8+OF8 -> 13182357711 | ON8: =OG8+OH8+OI8 -> 10150862586 | OP8: 50000000
B9: B2C | C9: PHI | J9: =SUM(D9:I9) -> 0 | L9: =M9/(N8+N9) -> 0.30244398 | M9: =G4/10^3 -> 5.995 | N9: =SUM(OP9:PT9)/10^9 -> 19.771852 | O9: =(Q9*1000-N9)/(31-DAY(TODAY())) -> 3797.9225 | P9: HPH | Q9: 41.796919 | R9: =N9/Q9 -> 0.47304569 | S9: 296037543 | T9: 1560591209 | U9: 1176778498 | V9: 1111046014 | W9: 438411528 | X9: 1485306668 | Y9: 1036447698 | Z9: 1102991512 | AA9: 954359736 | AB9: 1166725792 | AC9: 1336340483 | AD9: 284530184 | AE9: 928460800 | AF9: 1029427788 | AG9: 837073021 | AH9: 964647895 | AI9: 1188807080 | AJ9: 1272320373 | AK9: 396722581 | AL9: 1018281626 | AM9: 811637098 | AN9: 779258134 | AO9: 1140282490 | AP9: 1120556414 | AQ9: 1095428305 | AR9: 424900510 | AS9: 624723234 | AT9: 515530774 | AU9: 204647368 | AV9: 303407457 | AW9: 304551548 | AX9: 210426782 | AY9: 242108114 | AZ9: 861652136 | BA9: 781023616 | BB9: 821192222 | BC9: 764319232 | BD9: 998373670 | BE9: 1126196338 | BF9: 260957417 | BG9: 1128844895 | BH9: 686190432 | BI9: 600712793 | BJ9: 694354946 | BK9: 772460489 | BL9: 1130901987 | BM9: 250640141 | BN9: 1404546747 | BO9: 1165387943 | BP9: 1367923716 | BQ9: 982312588 | BR9: 888443896 | BS9: 1200605501 | BT9: 260771839 | BU9: 1837558458 | BV9: 1300649528 | BW9: 1045721259 | BX9: 958000682 | BY9: 1074352874 | BZ9: 1152874480 | CA9: 225415010 | CB9: 1765552506 | CC9: 1129874513 | CD9: 861133519 | CE9: 1039374137 | CF9: 1566907085 | CG9: 1310462284 | CH9: 209672256 | CI9: 1465167909 | CJ9: 1432893355 | CK9: 1136419241 | CL9: 801598594 | CM9: 1131635685 | CN9: 1135790590 | CO9: 274078502 | CP9: 1214682754 | CQ9: 1124725582 | CR9: 1395936692 | CS9: 1154668714 | CT9: 1153935619 | CU9: 1195715708 | CV9: 245382177 | CW9: 1347453467 | CX9: 873386462 | CY9: 1103573417 | CZ9: 1200901397 | DA9: 867908958 | DB9: 1429679921 | DC9: 309951255 | DD9: 1235169173 | DE9: 753290776 | DF9: 781790971 | DG9: 1141137229 | DH9: 1298108307 | DI9: 1191249302 | DJ9: 251408064 | DK9: 233746148 | DL9: 1645803547 | DM9: 1074810386 | DN9: 972826479 | DO9: 1242832154 | DP9: 1443878556 | DQ9: 216079511 | DR9: 1281185531 | DS9: 1268142675 | DT9: 1027021254 | DU9: 985126556 | DV9: 1325476868 | DW9: 1241385400 | DX9: 214664410 | DY9: 967196797 | DZ9: 877781047 | EA9: 964263561 | EB9: 1008854733 | EC9: 1140688985 | ED9: 1191098902 | EE9: 338086997 | EF9: 1507400729 | EG9: 1221089016 | EH9: 223982116 | EI9: 235753437 | EJ9: 1229850515 | EK9: 709738760 | EL9: 196419633 | EM9: 1468867007 | EN9: 1231284453 | EO9: 1031134826 | EP9: 1199797888 | EQ9: 1064881652 | ER9: 1509211403 | ES9: 260662688 | ET9: 1474817094 | EU9: 1095525165 | EV9: 997247235 | EW9: 999266097 | EX9: 1184223716 | EY9: 1070789044 | EZ9: 247725057 | FA9: 1138578459 | FB9: 958078322 | FC9: 982419289 | FD9: 1249389605 | FE9: 1339190681 | FF9: 1364417402 | FG9: 384368788 | FH9: 1571832471 | FI9: 1101442179 | FJ9: 828301455 | FK9: 1054234142 | FL9: 886344746 | FM9: 1313692700 | FN9: 257690765 | FO9: 1504715619 | FP9: 1098026408 | FQ9: 787409409 | FR9: 1342022397 | FS9: 1158122191 | FT9: 1203292437 | FU9: 199184155 | FV9: 1149779324 | FW9: 993743147 | FX9: 1165462045 | FY9: 1153028209 | FZ9: 871121402 | GA9: 1126662121 | GB9: 263619389 | GC9: 1470077240 | GD9: 857548564 | GE9: 1090680393 | GF9: 1094933696 | GG9: 979128477 | GH9: 1200730782 | GI9: 345193441 | GJ9: 1431744813 | GK9: 1112970595 | GL9: 949717960 | GM9: 1211752213 | GN9: 998260924 | GO9: 1127745352 | GP9: 228078692 | GQ9: 980849146 | GR9: 826156966 | GS9: 1045908924 | GT9: 1008607212 | GU9: 1406089571 | GV9: 996577287 | GW9: 306559581 | GX9: 1128605624 | GY9: 1208964944 | GZ9: 1365872920 | HA9: 1198441470 | HB9: 1273281983 | HC9: 1226174769 | HD9: 325102933 | HE9: 1161120355 | HF9: 948928492 | HG9: 1472492048 | HH9: 1203076891 | HI9: 1207474997 | HJ9: 1282252428 | HK9: 281013979 | HL9: 1228280968 | HM9: 1060682842 | HN9: 1156819982 | HO9: 1124037874 | HP9: 1173469958 | HQ9: 1038007931 | HR9: 312221787 | HS9: 1326633711 | HT9: 1454159687 | HU9: 1028446664 | HV9: 809824308 | HW9: 959636018 | HX9: 1460759160 | HY9: 116293264 | HZ9: 487397910 | IA9: 735187649 | IB9: 599419112 | IC9: 687800873 | ID9: 780236681 | IE9: 1459668088 | IF9: 375397543 | IG9: 1027524909 | IH9: 759126074 | II9: 1006409918 | IJ9: 1210771608 | IK9: 1106295519 | IL9: 1509297708 | IM9: 364758751 | IN9: 871170666 | IO9: 937813398 | IP9: 852456688 | IQ9: 897049197 | IR9: 987452797 | IS9: 1682287719 | IT9: 351850325 | IU9: 1341933516 | IV9: 1006112759 | IW9: 992409938 | IX9: 1035822645 | IY9: 1098643776 | IZ9: 1741798575 | JA9: 415725176 | JB9: 379647128 | JC9: 372142959 | JD9: 1103258438 | JE9: 986910648 | JF9: 924925516 | JG9: 1466906676 | JH9: 333984047 | JI9: 1327867885 | JJ9: 1125833872 | JK9: 834404643 | JL9: 896854811 | JM9: 746367297 | JN9: 1542637209 | JO9: 362261494 | JP9: 1184301305 | JQ9: 1081569936 | JR9: 1465509969 | JS9: 1031803849 | JT9: 1084060023 | JU9: 1533426888 | JV9: 392549744 | JW9: 1569398957 | JX9: 980282656 | JY9: 1227237678 | JZ9: 1145727974 | KA9: 1070382401 | KB9: 1564349683 | KC9: 322099722 | KD9: 1190864319 | KE9: 1043823784 | KF9: 863774918 | KG9: 889018124 | KH9: 1108953638 | KI9: 1534491290 | KJ9: 535969170 | KK9: 1552537894 | KL9: 995456468 | KM9: 1075646180 | KN9: 910613752 | KO9: 1322687968 | KP9: 1974371137 | KQ9: 731313050 | KR9: 1221845688 | KS9: 907094018 | KT9: 1006368768 | KU9: 977385061 | KV9: 1202559451 | KW9: 1334865633 | KX9: 425406364 | KY9: 1303924806 | KZ9: 935439622 | LA9: 1036926706 | LB9: 797596213 | LC9: 984192491 | LD9: 1560503866 | LE9: 518814403 | LF9: 1417571923 | LG9: 1057662920 | LH9: 1023815292 | LI9: 819958248 | LJ9: 1224757103 | LK9: 1420132173 | LL9: 500915687 | LM9: 1301738609 | LN9: 829410652 | LO9: 634884994 | LP9: 903742542 | LQ9: 1050870846 | LR9: 2026135537 | LS9: 513823482 | LT9: 1254747467 | LU9: 1347417432 | LV9: 883704973 | LW9: 1012418039 | LX9: 677569129 | LY9: 1504557478 | LZ9: 384696716 | MA9: 1326666394 | MB9: 1069763572 | MC9: 1085301593 | MD9: 892013647 | ME9: 1145128273 | MF9: 1695179001 | MG9: 455456129 | MH9: 1352066433 | MI9: 991479076 | MJ9: 1006352911 | MK9: 1006829085 | ML9: 1037999080 | MM9: 2011915906 | MN9: 724273882 | MO9: 1451629361 | MP9: 1833359131 | MQ9: 1551998974 | MR9: 1288717091 | MS9: 1350274223 | MT9: 1567154528 | MU9: 580436096 | MV9: 1402439059 | MW9: 1011102389 | MX9: 1249642001 | MY9: 1213492360 | MZ9: 1152166465 | NA9: 1577801634 | NB9: 484418427 | NC9: 1376557502 | ND9: 1268458536 | NE9: 1384909226 | NF9: 1234477350 | NG9: 1305111014 | NH9: 1420025542 | NI9: 421783948 | NJ9: 1142167213 | NK9: 1014122652 | NL9: 997044637 | NM9: 1364145948 | NN9: 1120154403 | NO9: 1241593229 | NP9: 618490301 | NQ9: 1217240694 | NR9: 1426313340 | NS9: 1192554268 | NW9: HMSG | NX9: =SUM(S9:AW9) -> 26910231361 | NY9: =SUM(AX9:BY9) -> 24816630241 | NZ9: =SUM(BZ9:DD9) -> 32491920962 | OA9: =SUM(DE9:EH9) -> 29030407007 | OB9: =SUM(EI9:FM9) -> 31379485909 | OC9: =SUM(FN9:GQ9) -> 29353291306 | OD9: =SUM(GR9:HV9) -> 32585289086 | OE9: =SUM(HW9:JA9) -> 28858507960 | OF9: =SUM(JB9:KE9) -> 30291391511 | OG9: =SUM(KF9:LJ9) -> 33251522165 | OH9: =SUM(LK9:MN9) -> 32047190738 | OI9: =SUM(MO9:NS9) -> 37459781542 | OJ9: =SUM(NX9:OI9) -> 368475649788 | OK9: =NX9+NY9+NZ9 -> 84218782564 | OL9: =OA9+OB9+OC9 -> 89763184222 | OM9: =OD9+OE9+OF9 -> 91735188557 | ON9: =OG9+OH9+OI9 -> 102758494445 | OP9: 4.3964399e+08 | OQ9: 1149665863 | OR9: 9.648375e+08 | OS9: 4.132283e+08 | OT9: 1714452126 | OU9: 1539934718 | OV9: 9.3516929e+08 | OW9: 961052937 | OX9: 1183402025 | OY9: 1577577053 | OZ9: 5.2978244e+08 | PA9: 1455582129 | PB9: 1140662005 | PC9: 9.2968411e+08 | PD9: 1170648194 | PE9: 8.8482854e+08 | PF9: 1584439404 | PG9: 3.8729757e+08 | PH9: 8.0996421e+08
